start!
Unhandled exception in listener callback
Traceback (most recent call last):
  File "C:\ProgramData\Anaconda3\lib\site-packages\pynput\_util\__init__.py", line 211, in inner
    return f(self, *args, **kwargs)
  File "C:\ProgramData\Anaconda3\lib\site-packages\pynput\keyboard\_win32.py", line 280, in _process
    self.on_press(key)
  File "C:\ProgramData\Anaconda3\lib\site-packages\pynput\_util\__init__.py", line 127, in inner
    if f(*args) is False:
  File "D:/Github/forza_motorsport/keyboardloop.py", line 84, in presskey
    if control.isRun:
AttributeError: 'ForzaControl' object has no attribute 'isRun'
start!
start!
start!
start!
start!
start!
listening on port 5300
start!
listening on port 5300
Unhandled exception in listener callback
Traceback (most recent call last):
  File "C:\ProgramData\Anaconda3\lib\site-packages\pynput\_util\__init__.py", line 211, in inner
    return f(self, *args, **kwargs)
  File "C:\ProgramData\Anaconda3\lib\site-packages\pynput\keyboard\_win32.py", line 280, in _process
    self.on_press(key)
  File "C:\ProgramData\Anaconda3\lib\site-packages\pynput\_util\__init__.py", line 127, in inner
    if f(*args) is False:
  File "D:/Github/forza_motorsport/keyboardloop.py", line 91, in presskey
    plt.plot(time,rpm,label='rpm')
  File "C:\ProgramData\Anaconda3\lib\site-packages\matplotlib\pyplot.py", line 2761, in plot
    return gca().plot(
  File "C:\ProgramData\Anaconda3\lib\site-packages\matplotlib\axes\_axes.py", line 1647, in plot
    lines = [*self._get_lines(*args, data=data, **kwargs)]
  File "C:\ProgramData\Anaconda3\lib\site-packages\matplotlib\axes\_base.py", line 216, in __call__
    yield from self._plot_args(this, kwargs)
  File "C:\ProgramData\Anaconda3\lib\site-packages\matplotlib\axes\_base.py", line 342, in _plot_args
    raise ValueError(f"x and y must have same first dimension, but "
ValueError: x and y must have same first dimension, but have shapes (1,) and (528,)
start!
listening on port 5300
start!
listening on port 5300
Unhandled exception in listener callback
Traceback (most recent call last):
  File "C:\ProgramData\Anaconda3\lib\site-packages\pynput\_util\__init__.py", line 211, in inner
    return f(self, *args, **kwargs)
  File "C:\ProgramData\Anaconda3\lib\site-packages\pynput\keyboard\_win32.py", line 280, in _process
    self.on_press(key)
  File "C:\ProgramData\Anaconda3\lib\site-packages\pynput\_util\__init__.py", line 127, in inner
    if f(*args) is False:
  File "D:/Github/forza_motorsport/keyboardloop.py", line 100, in presskey
    threadPool.submit(run )
  File "C:\ProgramData\Anaconda3\lib\concurrent\futures\thread.py", line 179, in submit
    raise RuntimeError('cannot schedule new futures after shutdown')
RuntimeError: cannot schedule new futures after shutdown
start!
listening on port 5300
start!
listening on port 5300
stop
stop
stop
stop
start!
listening on port 5300
stop
stop
start!
listening on port 5300
Unhandled exception in listener callback
Traceback (most recent call last):
  File "C:\ProgramData\Anaconda3\lib\site-packages\pynput\_util\__init__.py", line 211, in inner
    return f(self, *args, **kwargs)
  File "C:\ProgramData\Anaconda3\lib\site-packages\pynput\keyboard\_win32.py", line 280, in _process
    self.on_press(key)
  File "C:\ProgramData\Anaconda3\lib\site-packages\pynput\_util\__init__.py", line 127, in inner
    if f(*args) is False:
  File "D:/Github/forza_motorsport/keyboardloop.py", line 92, in presskey
    time0=ls[0].get('time')
IndexError: list index out of range
start!
listening on port 5300
Unhandled exception in listener callback
Traceback (most recent call last):
  File "C:\ProgramData\Anaconda3\lib\site-packages\pynput\_util\__init__.py", line 211, in inner
    return f(self, *args, **kwargs)
  File "C:\ProgramData\Anaconda3\lib\site-packages\pynput\keyboard\_win32.py", line 280, in _process
    self.on_press(key)
  File "C:\ProgramData\Anaconda3\lib\site-packages\pynput\_util\__init__.py", line 127, in inner
    if f(*args) is False:
  File "D:/Github/forza_motorsport/keyboardloop.py", line 92, in presskey
    time0=ls[0].get('time')
IndexError: list index out of range
start!
listening on port 5300
stop
stop
stop
stop
stop
start!
listening on port 5300
stop
start!
listening on port 5300
start!
listening on port 5300
stop
stop
stop
start!
listening on port 5300
stop
stop
start!
listening on port 5300
listening on port 5300
start!
listening on port 5300
listening on port 5300
listening on port 5300
start!
listening on port 5300
start!
listening on port 5300
stop
stop
stop
stop
stop
stop
stop
stop
stop
stop
stop
stop
stop
stop
stop
stop
stop
stop
start!
stop
stop
stop
stop
stop
stop
stop
stop
stop
stop
stop
stop
stop
stop
stop
stop
stop
start!
listening on port 5300
start!
start!
start!
listening on port 5300
start!
listening on port 5300
start!
listening on port 5300
start!
listening on port 5300
listening on port 5300
listening on port 5300
listening on port 5300
listening on port 5300
listening on port 5300
listening on port 5300
listening on port 5300
start!
start!
start!
listening on port 5300
listening on port 5300
listening on port 5300
listening on port 5300
start!
listening on port 5300
start!
listening on port 5300
start!
listening on port 5300
start!
start!
listening on port 5300
start!
listening on port 5300
start!
listening on port 5300
start!
start!
listening on port 5300
listening on port 5300
listening on port 5300
listening on port 5300
start!
listening on port 5300
listening on port 5300
start!
listening on port 5300
listening on port 5300
start!
listening on port 5300
start!
listening on port 5300
listening on port 5300
listening on port 5300
listening on port 5300
listening on port 5300
listening on port 5300
Unhandled exception in listener callback
Traceback (most recent call last):
  File "C:\ProgramData\Anaconda3\lib\site-packages\pynput\_util\__init__.py", line 211, in inner
    return f(self, *args, **kwargs)
  File "C:\ProgramData\Anaconda3\lib\site-packages\pynput\keyboard\_win32.py", line 280, in _process
    self.on_press(key)
  File "C:\ProgramData\Anaconda3\lib\site-packages\pynput\_util\__init__.py", line 127, in inner
    if f(*args) is False:
  File "D:/Github/forza_motorsport/keyboardloop.py", line 80, in presskey
    time0=ls[0].get('time')
IndexError: list index out of range
start!
listening on port 5300
listening on port 5300
listening on port 5300
listening on port 5300
listening on port 5300
start!
listening on port 5300
start!
listening on port 5300
Unhandled exception in listener callback
Traceback (most recent call last):
  File "C:\ProgramData\Anaconda3\lib\site-packages\pynput\_util\__init__.py", line 211, in inner
    return f(self, *args, **kwargs)
  File "C:\ProgramData\Anaconda3\lib\site-packages\pynput\keyboard\_win32.py", line 280, in _process
    self.on_press(key)
  File "C:\ProgramData\Anaconda3\lib\site-packages\pynput\_util\__init__.py", line 127, in inner
    if f(*args) is False:
  File "D:/Github/forza_motorsport/keyboardloop.py", line 93, in presskey
    json.dump(ls,open('record.json','wb',encoding='utf-8'))
ValueError: binary mode doesn't take an encoding argument
start!
listening on port 5300
start!
listening on port 5300
start!
listening on port 5300
Unhandled exception in listener callback
Traceback (most recent call last):
  File "C:\ProgramData\Anaconda3\lib\site-packages\pynput\_util\__init__.py", line 211, in inner
    return f(self, *args, **kwargs)
  File "C:\ProgramData\Anaconda3\lib\site-packages\pynput\keyboard\_win32.py", line 280, in _process
    self.on_press(key)
  File "C:\ProgramData\Anaconda3\lib\site-packages\pynput\_util\__init__.py", line 127, in inner
    if f(*args) is False:
  File "D:/Github/forza_motorsport/keyboardloop.py", line 82, in presskey
    time0=ls[0].get('time')
IndexError: list index out of range
start!
listening on port 5300
start!
listening on port 5300
listening on port 5300
start!
start!
listening on port 5300
start!
listening on port 5300
start!
start!
listening on port 5300
start!
listening on port 5300
start!
listening on port 5300
start!
start!
listening on port 5300
start!
start!
listening on port 5300
listening on port 5300
start!
listening on port 5300
start!
listening on port 5300
start!
listening on port 5300
start!
listening on port 5300
start!
listening on port 5300
start!
start!
listening on port 5300
start!
listening on port 5300
start!
listening on port 5300
start!
listening on port 5300
start!
listening on port 5300
start!
listening on port 5300
start!
listening on port 5300
start!
listening on port 5300
start!
listening on port 5300
start!
listening on port 5300
start!
listening on port 5300
start!
listening on port 5300
start!
listening on port 5300
Unhandled exception in listener callback
Traceback (most recent call last):
  File "C:\ProgramData\Anaconda3\lib\site-packages\pynput\_util\__init__.py", line 211, in inner
    return f(self, *args, **kwargs)
  File "C:\ProgramData\Anaconda3\lib\site-packages\pynput\keyboard\_win32.py", line 280, in _process
    self.on_press(key)
  File "C:\ProgramData\Anaconda3\lib\site-packages\pynput\_util\__init__.py", line 127, in inner
    if f(*args) is False:
  File "D:/Github/forza_motorsport/keyboardloop.py", line 73, in presskey
    ls=list(control.recordList)
AttributeError: 'ForzaControl' object has no attribute 'recordList'
start!
listening on port 5300
Unhandled exception in listener callback
Traceback (most recent call last):
  File "C:\ProgramData\Anaconda3\lib\site-packages\pynput\_util\__init__.py", line 211, in inner
    return f(self, *args, **kwargs)
  File "C:\ProgramData\Anaconda3\lib\site-packages\pynput\keyboard\_win32.py", line 280, in _process
    self.on_press(key)
  File "C:\ProgramData\Anaconda3\lib\site-packages\pynput\_util\__init__.py", line 127, in inner
    if f(*args) is False:
  File "D:/Github/forza_motorsport/keyboardloop.py", line 99, in presskey
    gearls=solveGearControlLs(ls)
  File "D:\Github\forza_motorsport\analyze.py", line 91, in solveGearControlLs
    controlLs = genGearControlLs(ls, gearLs)
  File "D:\Github\forza_motorsport\analyze.py", line 81, in genGearControlLs
    powerLast=findLastPower()
  File "D:\Github\forza_motorsport\analyze.py", line 70, in findLastPower
    lastPIndex = newRegion[-1]['index']
IndexError: list index out of range
start!
listening on port 5300
listening on port 5300
start!
listening on port 5300
start!
listening on port 5300
listening on port 5300
listening on port 5300
start!
listening on port 5300
start!
listening on port 5300
start!
listening on port 5300
listening on port 5300
start!
listening on port 5300
start!
listening on port 5300
start!
listening on port 5300
start!
start!
listening on port 5300
